<?xml version="1.0" encoding="utf-8"?>
<robot name="dvrk_psm" xmlns:xacro="http://www.ros.org/wiki/xacro">

  <xacro:macro name="psm_tool" params="prefix">
    <!-- joint 3: insertion (fixed) -->
    <joint name="outer_insertion" type="fixed">
      <parent link="${prefix}tool0"/>
      <child link="${prefix}tool_main_link"/>
      <axis xyz="0 0 1"/>
      <origin rpy="1.5708 0 0" xyz="0 0.4318 0"/>
    </joint>
      
    <!-- link 3: tool_main_link -->
    <link name="${prefix}tool_main_link">
      <visual>
        <origin rpy="0 0 1.5708" xyz="0 0 0.041"/>
        <geometry>
          <mesh filename="package://dvrk_model/meshes/psm/tool_main.dae"/>      
        </geometry>
      </visual>
    </link>
    
    <!-- joint 4: Outer Roll -->
    <joint name="outer_roll" type="revolute">
      <parent link="${prefix}tool_main_link"/>
      <child link="${prefix}tool_wrist_link"/>
      <axis xyz="0 0 1"/>
      <origin rpy="0 0 0" xyz="0 0 0.4162"/>
      <limit lower="-2.2689" upper="2.2689" velocity=".4" effort="1000"/>
    </joint>

    <!-- link 4: tool_wrist_link -->
    <link name="${prefix}tool_wrist_link">
      <visual>
        <origin rpy="0 0 1.5708" xyz="0 0 -0.0091"/>
        <geometry>
          <mesh filename="package://dvrk_model/meshes/psm/tool_wrist_link.dae"/>      
        </geometry>
      </visual>
    </link>

    <!-- joint 4-1: outer roll shaft joint FIXED-->
    <joint name="outer_roll_shaft" type="fixed">
      <parent link="${prefix}tool_wrist_link"/>
      <child link="${prefix}tool_wrist_shaft_link"/>
      <axis xyz="0 0 1"/>
      <origin rpy="0 0 0" xyz="0 0 0.0"/>
    </joint>

    <!-- link 4-1: tool_wrist_shaft_link -->
    <link name="${prefix}tool_wrist_shaft_link">
      <visual>
        <origin rpy="1.5708 0 0" xyz="0 0.00401 0"/>
        <geometry>
          <mesh filename="package://dvrk_model/meshes/psm/tool_wrist_shaft_link.dae"/> 
        </geometry>
      </visual>
    </link>
      
    <!-- joint 5: Outer wrist pitch joint -->
    <joint name="outer_wrist_pitch" type="revolute">
      <parent link="${prefix}tool_wrist_shaft_link"/>
      <child link="${prefix}tool_wrist_caudier_link"/>
      <axis xyz="0 0 1"/>
      <origin rpy="-1.5708 -1.5708 0" xyz="0 0 0"/>
      <limit lower="-1.5707" upper="1.5707" velocity=".4" effort="1000"/>
    </joint>
    
    <!-- link 5: tool_wrist_caudier_link -->
    <link name="${prefix}tool_wrist_caudier_link">
      <visual>
        <origin rpy="0.00 -1.5708 0.0" xyz="-0.0024 0.00 0.000"/>
        <geometry>
          <mesh filename="package://dvrk_model/meshes/psm/tool_wrist_caudier_link_1.stl"/>
        </geometry>
        <material name="gray"><color rgba="0.5 0.5 0.9 1.0"/></material>
      </visual>
      <collision>
        <origin rpy="0.00 -1.5708 0.0" xyz="-0.0024 0.00 0.000"/>
        <geometry>
          <mesh filename="package://dvrk_model/meshes/psm/tool_wrist_caudier_link_1.stl"/>
        </geometry>
      </collision>
    </link>

    <!-- joint 6: Tool wrist yaw joint -->
    <joint name="outer_wrist_yaw" type="revolute">
      <parent link="${prefix}tool_wrist_caudier_link"/>
      <child link="${prefix}tool_wrist_caudier_link_shaft"/>
      <axis xyz="0 0 1"/>
      <origin rpy="0.00 -1.5708 -1.5708" xyz="0.0091 0 0"/>
      <limit lower="-1.5707" upper="1.5707" velocity=".4" effort="1000"/>
    </joint>

    <!-- link 6: tool_wrist_caudier_link_shaft -->
    <link name="${prefix}tool_wrist_caudier_link_shaft">
      <visual>
        <origin rpy="0.00 1.5708 0.0" xyz="0.0 -0.0002 0.000"/>
        <geometry>
          <mesh filename="package://dvrk_model/meshes/psm/tool_wrist_caudier_link_1_shaft.stl"/>
        </geometry>
        <material name="gray"><color rgba="0.5 0.5 0.9 1.0"/></material>
      </visual>
      <collision>
        <origin rpy="0.00 1.5708 0.0" xyz="0.0 0.00 0.000"/>
        <geometry>
          <mesh filename="package://dvrk_model/meshes/psm/tool_wrist_caudier_link_1_shaft.stl"/>
        </geometry>
      </collision>
    </link>
    
    <!-- joint 7-0: Outer open angle 1  -->
    <joint name="jaw" type="revolute">
      <parent link="${prefix}tool_wrist_caudier_link_shaft"/>
      <child link="${prefix}tool_wrist_caudier_ee_link_0"/>      
      <axis xyz="0 0 1"/>
      <origin rpy="0 0 0" xyz="0 0 0"/>
      <limit lower="0" upper="1.5707" velocity=".4" effort="1000"/>
    </joint>

    <!-- link 7-0: Outer open angle virtual -->
    <link name="${prefix}tool_wrist_caudier_ee_link_0">
      <visual>
        <origin rpy="0 0 0" xyz="0 0 0"/>
        <geometry>          
          <box size="0 0 0" />
        </geometry>
      </visual>
    </link>

    <!-- joint 7-1: Outer open angle 1 -->
    <joint name="jaw_mimic_1" type="revolute">
      <parent link="${prefix}tool_wrist_caudier_link_shaft"/>
      <child link="${prefix}tool_wrist_caudier_link_2_left"/>
      <axis xyz="0 0 1"/>
      <origin rpy="0 0 0" xyz="0 0 0"/>
      <limit lower="0" upper="1.5707" velocity=".4" effort="1000"/>
      <mimic joint="jaw" multiplier="0.5"/>
    </joint>

    <!-- link 7-1: Outer open angle link 1 -->
    <link name="${prefix}tool_wrist_caudier_link_2_left">
      <visual>
        <origin rpy="0.0 0 0.0" xyz="0 0 0.00195"/>
        <geometry>
          <mesh filename="package://dvrk_model/meshes/psm/tool_wrist_caudier_link_2.stl"/>
        </geometry>
      </visual>     
    </link>

    <!-- joint 7-2: Outer open angle 2  -->
    <joint name="jaw_mimic_2" type="revolute">
      <parent link="${prefix}tool_wrist_caudier_link_shaft"/>
      <child link="${prefix}tool_wrist_caudier_link_2_right"/>
      <axis xyz="0 0 1"/>
      <origin rpy="3.1415926 0 0" xyz="0 0 0"/>
      <limit lower="0" upper="1.5707" velocity=".4" effort="1000"/>
      <mimic joint="jaw" multiplier="0.5"/>
    </joint>

    <!-- link 7-2: Outer open angle link 2 -->
    <link name="${prefix}tool_wrist_caudier_link_2_right">
      <visual>
        <origin rpy="0 0 -3.1415926" xyz="0 0 0.00195"/>
        <geometry>
          <mesh filename="package://dvrk_model/meshes/psm/tool_wrist_caudier_link_2.stl"/>
        </geometry>
      </visual>      
    </link>

    <!-- tool tip   -->
    <joint name="tool_wrist_caudier_ee" type="fixed">
      <parent link="${prefix}tool_wrist_caudier_link_shaft"/>
      <child link="${prefix}tool_wrist_caudier_ee_link"/>      
      <origin rpy="0.0 1.5708 1.5708" xyz="0 0 0"/>      
    </joint>

    <!-- link 6-3:  -->
    <link name="${prefix}tool_wrist_caudier_ee_link" />    

  </xacro:macro>

</robot>



